<?xml version="1.0"?>
<robot name="diffbot" xmlns:xacro="http://ros.org/wiki/xacro">
  <xacro:macro name="inertial" params="mass radius length">
    <inertial>
      <mass value="${mass}"/>
      <inertia ixx="${0.0833333*mass*radius*radius}" ixy="0.0" ixz="0.0"
               iyy="${0.0833333*mass*radius*radius}" iyz="0.0"
               izz="${0.0833333*mass*radius*radius}"/>
    </inertial>
  </xacro:macro>

  <!-- Base Link -->
  <link name="base_link">
    <visual>
      <geometry>
        <box size="0.5 0.3 0.1"/>
      </geometry>
      <material name="blue">
        <color rgba="0 0 1 1"/>
      </material>
    </visual>
    <collision>
      <geometry>
        <box size="0.5 0.3 0.1"/>
      </geometry>
    </collision>
    <xacro:inertial mass="5.0" radius="0.3" length="0.5"/>
  </link>

  <!-- Left Wheel -->
  <link name="left_wheel">
    <visual>
      <geometry>
        <cylinder radius="0.1" length="0.05"/>
      </geometry>
      <material name="black">
        <color rgba="0 0 0 1"/>
      </material>
    </visual>
    <collision>
      <geometry>
        <cylinder radius="0.1" length="0.05"/>
      </geometry>
    </collision>
    <xacro:inertial mass="0.5" radius="0.1" length="0.05"/>
  </link>

  <!-- Right Wheel -->
  <link name="right_wheel">
    <visual>
      <geometry>
        <cylinder radius="0.1" length="0.05"/>
      </geometry>
      <material name="black"/>
    </visual>
    <collision>
      <geometry>
        <cylinder radius="0.1" length="0.05"/>
      </geometry>
    </collision>
    <xacro:inertial mass="0.5" radius="0.1" length="0.05"/>
  </link>

  <!-- Caster Wheel -->
  <link name="caster_wheel">
    <visual>
      <geometry>
        <sphere radius="0.05"/>
      </geometry>
      <material name="silver">
        <color rgba="0.7 0.7 0.7 1"/>
      </material>
    </visual>
    <collision>
      <geometry>
        <sphere radius="0.05"/>
      </geometry>
    </collision>
    <xacro:inertial mass="0.1" radius="0.05" length="0.05"/>
  </link>

  <!-- LIDAR -->
  <link name="lidar_link">
    <visual>
      <geometry>
        <cylinder radius="0.05" length="0.05"/>
      </geometry>
      <material name="red">
        <color rgba="1 0 0 1"/>
      </material>
    </visual>
    <collision>
      <geometry>
        <cylinder radius="0.05" length="0.05"/>
      </geometry>
    </collision>
    <xacro:inertial mass="0.2" radius="0.05" length="0.05"/>
  </link>

  <!-- Camera -->
  <link name="camera_link">
    <visual>
      <geometry>
        <box size="0.05 0.05 0.05"/>
      </geometry>
      <material name="green">
        <color rgba="0 1 0 1"/>
      </material>
    </visual>
    <collision>
      <geometry>
        <box size="0.05 0.05 0.05"/>
      </geometry>
    </collision>
    <xacro:inertial mass="0.1" radius="0.05" length="0.05"/>
  </link>

  <!-- Joints -->
  <joint name="base_to_left_wheel" type="continuous">
    <parent link="base_link"/>
    <child link="left_wheel"/>
    <origin xyz="0 0.2 -0.05" rpy="1.5708 0 0"/>
    <axis xyz="0 0 1"/>
  </joint>
  <joint name="base_to_right_wheel" type="continuous">
    <parent link="base_link"/>
    <child link="right_wheel"/>
    <origin xyz="0 -0.2 -0.05" rpy="1.5708 0 0"/>
    <axis xyz="0 0 1"/>
  </joint>
  <joint name="base_to_caster" type="fixed">
    <parent link="base_link"/>
    <child link="caster_wheel"/>
    <origin xyz="0.2 0 -0.1"/>
  </joint>
  <joint name="base_to_lidar" type="fixed">
    <parent link="base_link"/>
    <child link="lidar_link"/>
    <origin xyz="0.2 0 0.1"/>
  </joint>
  <joint name="base_to_camera" type="fixed">
    <parent link="base_link"/>
    <child link="camera_link"/>
    <origin xyz="0.25 0 0.05"/>
  </joint>

  <!-- Gazebo Plugins -->
  <gazebo reference="lidar_link">
    <sensor type="ray" name="lidar">
      <pose>0 0 0 0 0 0</pose>
      <ray>
        <scan>
          <horizontal>
            <samples>360</samples>
            <resolution>1</resolution>
            <min_angle>-3.14159</min_angle>
            <max_angle>3.14159</max_angle>
          </horizontal>
        </scan>
        <range>
          <min>0.1</min>
          <max>12.0</max>
          <resolution>0.01</resolution>
        </range>
      </ray>
      <plugin name="lidar_plugin" filename="libgazebo_ros_laser.so">
        <topicName>/scan</topicName>
        <frameName>lidar_link</frameName>
      </plugin>
    </sensor>
  </gazebo>
  <gazebo reference="camera_link">
    <sensor type="camera" name="camera">
      <pose>0 0 0 0 0 0</pose>
      <camera>
        <horizontal_fov>1.047</horizontal_fov>
        <image>
          <width>640</width>
          <height>480</height>
        </image>
        <clip>
          <near>0.1</near>
          <far>100</far>
        </clip>
      </camera>
      <plugin name="camera_plugin" filename="libgazebo_ros_camera.so">
        <topicName>/camera/image_raw</topicName>
        <frameName>camera_link</frameName>
      </plugin>
    </sensor>
  </gazebo>
  <gazebo>
    <plugin name="diff_drive" filename="libgazebo_ros_diff_drive.so">
      <ros>
        <namespace>/diffbot</namespace>
      </ros>
      <left_joint>base_to_left_wheel</left_joint>
      <right_joint>base_to_right_wheel</right_joint>
      <wheel_separation>0.4</wheel_separation>
      <wheel_diameter>0.2</wheel_diameter>
      <max_wheel_torque>10.0</max_wheel_torque>
      <max_wheel_acceleration>5.0</max_wheel_acceleration>
      <odometry_frame>odom</odometry_frame>
      <robot_base_frame>base_link</robot_base_frame>
      <publish_odom>true</publish_odom>
      <publish_odom_tf>true</publish_odom_tf>
      <topicName>cmd_vel</topicName>
    </plugin>
  </gazebo>
</robot>