<?xml version="1.0"?>
<robot name="gesture_arm">

  <link name="base_link">
    <visual>
      <geometry>
        <cylinder radius="0.1" length="0.2"/>
      </geometry>
      <origin xyz="0 0 0" rpy="0 0 0" />
      <material name="blue">
        <color rgba="0.0 0.0 1.0 1.0"/>
      </material>
    </visual>
  </link>

  <joint name="joint1" type="revolute">
    <parent link="base_link"/>
    <child link="link1"/>
    <origin xyz="0 0 0.1" rpy="0 0 0"/>
    <axis xyz="0 0 1"/>
    <limit lower="-1.57" upper="1.57" effort="10.0" velocity="1.0"/>
  </joint>

  <link name="link1">
    <visual>
      <geometry>
        <cylinder radius="0.05" length="0.3"/>
      </geometry>
      <origin xyz="0 0 0.15" rpy="0 0 0"/>
      <material name="red">
        <color rgba="1.0 0.0 0.0 1.0"/>
      </material>
    </visual>
  </link>

  <joint name="joint2" type="revolute">
    <parent link="link1"/>
    <child link="link2"/>
    <origin xyz="0 0 0.3" rpy="0 0 0"/>
    <axis xyz="0 1 0"/>
    <limit lower="-1.57" upper="1.57" effort="10.0" velocity="1.0"/>
  </joint>

  <link name="link2">
    <visual>
      <geometry>
        <cylinder radius="0.04" length="0.25"/>
      </geometry>
      <origin xyz="0 0 0.125" rpy="0 0 0"/>
      <material name="green">
        <color rgba="0.0 1.0 0.0 1.0"/>
      </material>
    </visual>
  </link>

  <joint name="joint3" type="revolute">
    <parent link="link2"/>
    <child link="link3"/>
    <origin xyz="0 0 0.25" rpy="0 0 0"/>
    <axis xyz="0 1 0"/>
    <limit lower="-1.57" upper="1.57" effort="10.0" velocity="1.0"/>
  </joint>
  
  <link name="link3">
    <visual>
      <geometry>
        <cylinder radius="0.03" length="0.2"/>
      </geometry>
      <origin xyz="0 0 0.1" rpy="0 0 0"/>
      <material name="yellow">
        <color rgba="1.0 1.0 0.0 1.0"/>
      </material>
    </visual>
  </link>

  <joint name="joint4" type="revolute">
    <parent link="link3"/>
    <child link="end_effector"/>
    <origin xyz="0 0 0.2" rpy="0 0 0"/>
    <axis xyz="0 1 0"/>
    <limit lower="-1.57" upper="1.57" effort="10.0" velocity="1.0"/>
  </joint>

  <link name="end_effector">
    <visual>
      <geometry>
        <sphere radius="0.05"/>
      </geometry>
      <origin xyz="0 0 0" rpy="0 0 0"/>
      <material name="black">
        <color rgba="0.0 0.0 0.0 1.0"/>
      </material>
    </visual>
  </link>

  <!-- Gripper base joint -->
  <joint name="gripper_joint" type="fixed">
    <parent link="end_effector"/>
    <child link="gripper_base"/>
    <origin xyz="0 0 0.05" rpy="0 0 0"/>
  </joint>

  <!-- Gripper base link -->
  <link name="gripper_base">
    <visual>
      <geometry>
        <box size="0.08 0.04 0.02"/>
      </geometry>
      <origin xyz="0 0 0" rpy="0 0 0"/>
      <material name="gray">
        <color rgba="0.5 0.5 0.5 1.0"/>
      </material>
    </visual>
  </link>

  <!-- Left finger joint -->
  <joint name="left_finger_joint" type="prismatic">
    <parent link="gripper_base"/>
    <child link="left_finger"/>
    <origin xyz="0.04 0.0 0.02" rpy="0 0 0"/>
    <axis xyz="0 1 0"/>
    <limit lower="-0.03" upper="0.0" effort="5.0" velocity="0.1"/>
  </joint>

  <!-- Left finger link -->
  <link name="left_finger">
    <visual>
      <geometry>
        <box size="0.02 0.01 0.06"/>
      </geometry>
      <origin xyz="0 0 0.03" rpy="0 0 0"/>
      <material name="orange">
        <color rgba="1.0 0.5 0.0 1.0"/>
      </material>
    </visual>
  </link>

  <!-- Right finger joint -->
  <joint name="right_finger_joint" type="prismatic">
    <parent link="gripper_base"/>
    <child link="right_finger"/>
    <origin xyz="0.04 0.0 0.02" rpy="0 0 3.14159"/>
    <axis xyz="0 1 0"/>
    <limit lower="-0.03" upper="0.0" effort="5.0" velocity="0.1"/>
  </joint>

  <!-- Right finger link -->
  <link name="right_finger">
    <visual>
      <geometry>
        <box size="0.02 0.01 0.06"/>
      </geometry>
      <origin xyz="0 0 0.03" rpy="0 0 0"/>
      <material name="orange">
        <color rgba="1.0 0.5 0.0 1.0"/>
      </material>
    </visual>
  </link>

</robot>