<?xml version="1.0" ?>
<!-- =================================================================================== -->
<!-- |    This document was autogenerated by xacro from my_dd_robot_model.xacro        | -->
<!-- |    EDITING THIS FILE BY HAND IS NOT RECOMMENDED                                 | -->
<!-- =================================================================================== -->
<robot name="gesture_arm">
  <link name="base_link">
    <visual>
      <origin rpy="0 0 0" xyz="0 0 0.05"/>
      <geometry>
        <cylinder length="0.1" radius="0.35"/>
      </geometry>
      <material name="">
        <color rgba="0.0 0.0 1.0 1.0"/>
      </material>
    </visual>
    <collision>
      <origin rpy="0 0 0" xyz="0 0 0.05"/>
      <geometry>
        <cylinder length="0.1" radius="0.35"/>
      </geometry>
    </collision>
    <inertial>
      <origin rpy="0 0 0" xyz="0 0 0.05"/>
      <mass value="15.0"/>
      <inertia ixx="0.6" ixy="0.0" ixz="0.0" iyy="0.6" iyz="0.0" izz="1.0"/>
    </inertial>
  </link>
  <link name="chassis_base">
    <visual>
      <origin rpy="0 0 0" xyz="0 0 0.04"/>
      <geometry>
        <box size="0.65 0.5 0.08"/>
      </geometry>
      <material name="">
        <color rgba="0.3 0.3 0.3 1.0"/>
      </material>
    </visual>
    <collision>
      <origin rpy="0 0 0" xyz="0 0 0.04"/>
      <geometry>
        <box size="0.65 0.5 0.08"/>
      </geometry>
    </collision>
    <inertial>
      <origin rpy="0 0 0" xyz="0 0 0.04"/>
      <mass value="10.0"/>
      <inertia ixx="0.21366666666666667" ixy="0.0" ixz="0.0" iyy="0.35741666666666666" iyz="0.0" izz="0.5604166666666667"/>
    </inertial>
  </link>
  <joint name="chassis_joint" type="fixed">
    <parent link="base_link"/>
    <child link="chassis_base"/>
    <origin rpy="0 0 0" xyz="0 0 0"/>
  </joint>
  <link name="wheel_mount_plate">
    <visual>
      <origin rpy="0 0 0" xyz="0 0 0.025"/>
      <geometry>
        <box size="0.55 0.6 0.05"/>
      </geometry>
      <material name="">
        <color rgba="0.2 0.2 0.2 1.0"/>
      </material>
    </visual>
    <collision>
      <origin rpy="0 0 0" xyz="0 0 0.025"/>
      <geometry>
        <box size="0.55 0.6 0.05"/>
      </geometry>
    </collision>
    <inertial>
      <origin rpy="0 0 0" xyz="0 0 0.025"/>
      <mass value="5.0"/>
      <inertia ixx="0.15104166666666666" ixy="0.0" ixz="0.0" iyy="0.12708333333333335" iyz="0.0" izz="0.2760416666666667"/>
    </inertial>
  </link>
  <joint name="wheel_mount_joint" type="fixed">
    <parent link="base_link"/>
    <child link="wheel_mount_plate"/>
    <origin rpy="0 0 0" xyz="0 0 -0.05"/>
  </joint>
  <link name="front_left_wheel">
    <visual>
      <origin rpy="1.5708 0 0" xyz="0 0 0"/>
      <geometry>
        <cylinder length="0.08" radius="0.1"/>
      </geometry>
      <material name="">
        <color rgba="0.0 0.0 0.0 1.0"/>
      </material>
    </visual>
    <collision>
      <origin rpy="1.5708 0 0" xyz="0 0 0"/>
      <geometry>
        <cylinder length="0.08" radius="0.1"/>
      </geometry>
    </collision>
    <inertial>
      <origin rpy="1.5708 0 0" xyz="0 0 0"/>
      <mass value="1.2"/>
      <inertia ixx="0.0036400000000000004" ixy="0.0" ixz="0.0" iyy="0.0036400000000000004" iyz="0.0" izz="0.006"/>
    </inertial>
  </link>
  <joint name="front_left_wheel_joint" type="continuous">
    <parent link="wheel_mount_plate"/>
    <child link="front_left_wheel"/>
    <origin rpy="0 0 0" xyz="0.225 0.275 0"/>
    <axis xyz="0 1 0"/>
    <dynamics damping="0.1" friction="0.1"/>
  </joint>
  <link name="front_right_wheel">
    <visual>
      <origin rpy="1.5708 0 0" xyz="0 0 0"/>
      <geometry>
        <cylinder length="0.08" radius="0.1"/>
      </geometry>
      <material name="">
        <color rgba="0.0 0.0 0.0 1.0"/>
      </material>
    </visual>
    <collision>
      <origin rpy="1.5708 0 0" xyz="0 0 0"/>
      <geometry>
        <cylinder length="0.08" radius="0.1"/>
      </geometry>
    </collision>
    <inertial>
      <origin rpy="1.5708 0 0" xyz="0 0 0"/>
      <mass value="1.2"/>
      <inertia ixx="0.0036400000000000004" ixy="0.0" ixz="0.0" iyy="0.0036400000000000004" iyz="0.0" izz="0.006"/>
    </inertial>
  </link>
  <joint name="front_right_wheel_joint" type="continuous">
    <parent link="wheel_mount_plate"/>
    <child link="front_right_wheel"/>
    <origin rpy="0 0 0" xyz="0.225 -0.275 0"/>
    <axis xyz="0 1 0"/>
    <dynamics damping="0.1" friction="0.1"/>
  </joint>
  <link name="rear_left_wheel">
    <visual>
      <origin rpy="1.5708 0 0" xyz="0 0 0"/>
      <geometry>
        <cylinder length="0.08" radius="0.1"/>
      </geometry>
      <material name="">
        <color rgba="0.0 0.0 0.0 1.0"/>
      </material>
    </visual>
    <collision>
      <origin rpy="1.5708 0 0" xyz="0 0 0"/>
      <geometry>
        <cylinder length="0.08" radius="0.1"/>
      </geometry>
    </collision>
    <inertial>
      <origin rpy="1.5708 0 0" xyz="0 0 0"/>
      <mass value="1.2"/>
      <inertia ixx="0.0036400000000000004" ixy="0.0" ixz="0.0" iyy="0.0036400000000000004" iyz="0.0" izz="0.006"/>
    </inertial>
  </link>
  <joint name="rear_left_wheel_joint" type="continuous">
    <parent link="wheel_mount_plate"/>
    <child link="rear_left_wheel"/>
    <origin rpy="0 0 0" xyz="-0.225 0.275 0"/>
    <axis xyz="0 1 0"/>
    <dynamics damping="0.1" friction="0.1"/>
  </joint>
  <link name="rear_right_wheel">
    <visual>
      <origin rpy="1.5708 0 0" xyz="0 0 0"/>
      <geometry>
        <cylinder length="0.08" radius="0.1"/>
      </geometry>
      <material name="">
        <color rgba="0.0 0.0 0.0 1.0"/>
      </material>
    </visual>
    <collision>
      <origin rpy="1.5708 0 0" xyz="0 0 0"/>
      <geometry>
        <cylinder length="0.08" radius="0.1"/>
      </geometry>
    </collision>
    <inertial>
      <origin rpy="1.5708 0 0" xyz="0 0 0"/>
      <mass value="1.2"/>
      <inertia ixx="0.0036400000000000004" ixy="0.0" ixz="0.0" iyy="0.0036400000000000004" iyz="0.0" izz="0.006"/>
    </inertial>
  </link>
  <joint name="rear_right_wheel_joint" type="continuous">
    <parent link="wheel_mount_plate"/>
    <child link="rear_right_wheel"/>
    <origin rpy="0 0 0" xyz="-0.225 -0.275 0"/>
    <axis xyz="0 1 0"/>
    <dynamics damping="0.1" friction="0.1"/>
  </joint>
  <link name="arm_mount">
    <visual>
      <origin rpy="0 0 0" xyz="0 0 0.2"/>
      <geometry>
        <cylinder length="0.4" radius="0.08"/>
      </geometry>
      <material name="">
        <color rgba="0.4 0.4 0.4 1.0"/>
      </material>
    </visual>
    <collision>
      <origin rpy="0 0 0" xyz="0 0 0.2"/>
      <geometry>
        <cylinder length="0.4" radius="0.08"/>
      </geometry>
    </collision>
    <inertial>
      <origin rpy="0 0 0" xyz="0 0 0.2"/>
      <mass value="6.0"/>
      <inertia ixx="0.08960000000000001" ixy="0.0" ixz="0.0" iyy="0.08960000000000001" iyz="0.0" izz="0.0192"/>
    </inertial>
  </link>
  <joint name="arm_mount_joint" type="fixed">
    <parent link="base_link"/>
    <child link="arm_mount"/>
    <origin rpy="0 0 0" xyz="0 0 0.1"/>
  </joint>

  <joint name="shoulder_yaw_joint" type="revolute">
    <parent link="arm_mount"/>
    <child link="shoulder_base"/>
    <origin rpy="0 0 0" xyz="0 0 0.4"/>
    <axis xyz="0 0 1"/>
    <limit effort="150.0" lower="-3.14" upper="3.14" velocity="2.0"/>
    <dynamics damping="1.0" friction="0.5"/>
  </joint>
  <link name="shoulder_base">
    <visual>
      <origin rpy="0 0 0" xyz="0 0 0.04"/>
      <geometry>
        <cylinder length="0.08" radius="0.07"/>
      </geometry>
      <material name="">
        <color rgba="0.7 0.0 0.0 1.0"/>
      </material>
    </visual>
    <collision>
      <origin rpy="0 0 0" xyz="0 0 0.04"/>
      <geometry>
        <cylinder length="0.08" radius="0.07"/>
      </geometry>
    </collision>
    <inertial>
      <origin rpy="0 0 0" xyz="0 0 0.04"/>
      <mass value="2.0"/>
      <inertia ixx="0.003516666666666667" ixy="0.0" ixz="0.0" iyy="0.003516666666666667" iyz="0.0" izz="0.004900000000000001"/>
    </inertial>
  </link>

  <joint name="shoulder_pitch_joint" type="revolute">
    <parent link="shoulder_base"/>
    <child link="upper_arm_link"/>
    <origin rpy="0 0 0" xyz="0 0 0.08"/>
    <axis xyz="0 1 0"/>
    <limit effort="120.0" lower="-2.0" upper="2.0" velocity="1.8"/>
    <dynamics damping="0.8" friction="0.2"/>
  </joint>
  <link name="upper_arm_link">
    <visual>
      <origin rpy="0 0 0" xyz="0 0 0.15"/>
      <geometry>
        <cylinder length="0.3" radius="0.05"/>
      </geometry>
      <material name="">
        <color rgba="0.8 0.0 0.0 1.0"/>
      </material>
    </visual>
    <collision>
      <origin rpy="0 0 0" xyz="0 0 0.15"/>
      <geometry>
        <cylinder length="0.3" radius="0.05"/>
      </geometry>
    </collision>
    <inertial>
      <origin rpy="0 0 0" xyz="0 0 0.15"/>
      <mass value="1.5"/>
      <inertia ixx="0.0121875" ixy="0.0" ixz="0.0" iyy="0.0121875" iyz="0.0" izz="0.0018750000000000004"/>
    </inertial>
  </link>

  <joint name="elbow_joint" type="revolute">
    <parent link="upper_arm_link"/>
    <child link="forearm_link"/>
    <origin rpy="0 -0.2 0" xyz="0 0 0.3"/>
    <axis xyz="0 1 0"/>
    <limit effort="80.0" lower="-2.5" upper="2.5" velocity="2.0"/>
    <dynamics damping="0.5" friction="0.1"/>
  </joint>
  <link name="forearm_link">
    <visual>
      <origin rpy="0 0 0" xyz="0 0 0.125"/>
      <geometry>
        <cylinder length="0.25" radius="0.045"/>
      </geometry>
      <material name="">
        <color rgba="0.0 1.0 0.0 1.0"/>
      </material>
    </visual>
    <collision>
      <origin rpy="0 0 0" xyz="0 0 0.125"/>
      <geometry>
        <cylinder length="0.25" radius="0.045"/>
      </geometry>
    </collision>
    <inertial>
      <origin rpy="0 0 0" xyz="0 0 0.125"/>
      <mass value="1.0"/>
      <inertia ixx="0.005714583333333333" ixy="0.0" ixz="0.0" iyy="0.005714583333333333" iyz="0.0" izz="0.0010125"/>
    </inertial>
  </link>

  <joint name="wrist_roll_joint" type="revolute">
    <parent link="forearm_link"/>
    <child link="wrist_roll_link"/>
    <origin rpy="0 -0.1 0" xyz="0 0 0.25"/>
    <axis xyz="1 0 0"/>
    <limit effort="40.0" lower="-3.14" upper="3.14" velocity="3.0"/>
    <dynamics damping="0.1" friction="0.05"/>
  </joint>
  <link name="wrist_roll_link">
    <visual>
      <origin rpy="0 0 0" xyz="0 0 0.03"/>
      <geometry>
        <cylinder length="0.06" radius="0.04"/>
      </geometry>
      <material name="">
        <color rgba="0.0 0.8 0.8 1.0"/>
      </material>
    </visual>
    <collision>
      <origin rpy="0 0 0" xyz="0 0 0.03"/>
      <geometry>
        <cylinder length="0.06" radius="0.04"/>
      </geometry>
    </collision>
    <inertial>
      <origin rpy="0 0 0" xyz="0 0 0.03"/>
      <mass value="0.4"/>
      <inertia ixx="0.00028" ixy="0.0" ixz="0.0" iyy="0.00028" iyz="0.0" izz="0.00032"/>
    </inertial>
  </link>
  <joint name="wrist_pitch_joint" type="revolute">
    <parent link="wrist_roll_link"/>
    <child link="wrist_pitch_link"/>
    <origin rpy="0 0 0" xyz="0 0 0.06"/>
    <axis xyz="0 1 0"/>
    <limit effort="30.0" lower="-1.57" upper="1.57" velocity="3.0"/>
    <dynamics damping="0.1" friction="0.05"/>
  </joint>
  <link name="wrist_pitch_link">
    <visual>
      <origin rpy="0 0 0" xyz="0 0 0.025"/>
      <geometry>
        <cylinder length="0.05" radius="0.035"/>
      </geometry>
      <material name="">
        <color rgba="1.0 1.0 0.0 1.0"/>
      </material>
    </visual>
    <collision>
      <origin rpy="0 0 0" xyz="0 0 0.025"/>
      <geometry>
        <cylinder length="0.05" radius="0.035"/>
      </geometry>
    </collision>
    <inertial>
      <origin rpy="0 0 0" xyz="0 0 0.025"/>
      <mass value="0.3"/>
      <inertia ixx="0.00015437500000000003" ixy="0.0" ixz="0.0" iyy="0.00015437500000000003" iyz="0.0" izz="0.00018375000000000002"/>
    </inertial>
  </link>
  <joint name="end_effector_joint" type="fixed">
    <parent link="wrist_pitch_link"/>
    <child link="end_effector"/>
    <origin rpy="0 -0.1 0" xyz="0 0 0.05"/>
  </joint>
  <link name="end_effector">
    <visual>
      <origin rpy="0 0 0" xyz="0 0 0.01"/>
      <geometry>
        <cylinder length="0.02" radius="0.03"/>
      </geometry>
      <material name="">
        <color rgba="0.0 0.0 0.0 1.0"/>
      </material>
    </visual>
    <collision>
      <origin rpy="0 0 0" xyz="0 0 0.01"/>
      <geometry>
        <cylinder length="0.02" radius="0.03"/>
      </geometry>
    </collision>
    <inertial>
      <origin rpy="0 0 0" xyz="0 0 0.01"/>
      <mass value="0.2"/>
      <inertia ixx="5.1666666666666664e-05" ixy="0.0" ixz="0.0" iyy="5.1666666666666664e-05" iyz="0.0" izz="8.999999999999999e-05"/>
    </inertial>
  </link>
  <joint name="gripper_base_joint" type="fixed">
    <parent link="end_effector"/>
    <child link="gripper_base"/>
    <origin rpy="0 0 0" xyz="0 0 0.02"/>
  </joint>
  <link name="gripper_base">
    <visual>
      <origin rpy="0 0 0" xyz="0 0 0"/>
      <geometry>
        <box size="0.08 0.06 0.02"/>
      </geometry>
      <material name="">
        <color rgba="0.5 0.5 0.5 1.0"/>
      </material>
    </visual>
    <collision>
      <origin rpy="0 0 0" xyz="0 0 0"/>
      <geometry>
        <box size="0.08 0.06 0.02"/>
      </geometry>
    </collision>
    <inertial>
      <origin rpy="0 0 0" xyz="0 0 0"/>
      <mass value="0.2"/>
      <inertia ixx="6.666666666666667e-05" ixy="0.0" ixz="0.0" iyy="0.00011333333333333334" iyz="0.0" izz="0.00016666666666666666"/>
    </inertial>
  </link>
  <joint name="left_finger_joint" type="prismatic">
    <parent link="gripper_base"/>
    <child link="left_finger"/>
    <origin rpy="0 0 0" xyz="0.04 0.02 0.01"/>
    <axis xyz="0 1 0"/>
    <limit effort="15.0" lower="0.0" upper="0.03" velocity="0.5"/>
    <dynamics damping="0.01" friction="0.01"/>
  </joint>
  <link name="left_finger">
    <visual>
      <origin rpy="0 0 0" xyz="0 0 0.03"/>
      <geometry>
        <box size="0.03 0.01 0.06"/>
      </geometry>
      <material name="">
        <color rgba="1.0 0.5 0.0 1.0"/>
      </material>
    </visual>
    <collision>
      <origin rpy="0 0 0" xyz="0 0 0.03"/>
      <geometry>
        <box size="0.03 0.01 0.06"/>
      </geometry>
    </collision>
    <inertial>
      <origin rpy="0 0 0" xyz="0 0 0.03"/>
      <mass value="0.05"/>
      <inertia ixx="1.5416666666666664e-05" ixy="0.0" ixz="0.0" iyy="1.875e-05" iyz="0.0" izz="4.166666666666667e-06"/>
    </inertial>
  </link>
  <joint name="right_finger_joint" type="prismatic">
    <parent link="gripper_base"/>
    <child link="right_finger"/>
    <origin rpy="0 0 0" xyz="0.04 -0.02 0.01"/>
    <axis xyz="0 -1 0"/>
    <limit effort="15.0" lower="0.0" upper="0.03" velocity="0.5"/>
    <dynamics damping="0.01" friction="0.01"/>
    <mimic joint="left_finger_joint" multiplier="1" offset="0"/>
  </joint>
  <link name="right_finger">
    <visual>
      <origin rpy="0 0 0" xyz="0 0 0.03"/>
      <geometry>
        <box size="0.03 0.01 0.06"/>
      </geometry>
      <material name="">
        <color rgba="1.0 0.5 0.0 1.0"/>
      </material>
    </visual>
    <collision>
      <origin rpy="0 0 0" xyz="0 0 0.03"/>
      <geometry>
        <box size="0.03 0.01 0.06"/>
      </geometry>
    </collision>
    <inertial>
      <origin rpy="0 0 0" xyz="0 0 0.03"/>
      <mass value="0.05"/>
      <inertia ixx="1.5416666666666664e-05" ixy="0.0" ixz="0.0" iyy="1.875e-05" iyz="0.0" izz="4.166666666666667e-06"/>
    </inertial>
  </link>
</robot>
