<?xml version="1.0"?>


<robot xmlns:xacro = "http://www.ros.org/wiki/xacro" name="my_dd_robot">




<xacro:property name="x_dim" value="0.6"/>
<xacro:property name="y_dim" value="0.4"/>
<xacro:property name="z_dim" value="0.2"/>
<xacro:property name="robotname" value="my_dd"/>
<xacro:property name= "wheel_radius" value = "0.1"/>
<xacro:property name= "wheel_thickness" value = "0.05"/>
<xacro:property name= "wheel_mass" value = "0.15"/>

<xacro:macro name="inertial" params="mass">
        <inertial>
            <mass value="${mass}"/>
            <inertia ixx="1e-3" ixy = "0.0" ixz="0.0" iyy="1e-3" iyz="0.0" izz="1e-3"/>
            <origin xyz="0.0 0.0 0.0" rpy="0.0 0.0 0.0"/> 
        </inertial>
</xacro:macro>

<!--must be included only after defining xacro properties and macros-->
<xacro:include filename="$(find my_ddrobot)/model/my_dd_robot.gazebo"/>


    <material name="grey">
        <color rgba="0.7 0.7 0.7 1" />
    </material>

    <material name="green">
        <color rgba="0 0.6 0 1" />
    </material>
    
    <material name="white">
        <color rgba="1 1 1 1"/>
    </material>

    <material name="yellow">
        <color rgba="1 1 0 1"/>
    </material>

<!-- Base Footprint -->
    <link name="base_footprint"/>

<!-- Base link ; Body of the robot -->
    <link name="base_link">
        <visual>
            <geometry>
                <box size="${x_dim} ${y_dim} ${z_dim}" />
            </geometry>
            <origin xyz="0 0 0.1" rpy="0 0 0" />
            <material name="green" />
        </visual>

<!-- Collision Geometry-->
    <collision>
        <geometry>
            <box size="${x_dim} ${y_dim} ${z_dim}" />
        </geometry>
    </collision>

<!-- Inertial Properties-->
    <xacro:inertial mass="2"/>
    </link>
    

    <link name="left_wheel">
        <visual>
            <geometry>
                <cylinder radius="${wheel_radius}" length="${wheel_thickness}"/>
            </geometry>
            <origin xyz="0 0 0" rpy="1.57 0 0" />
            <material name="grey" />
        </visual>
        <collision>
            <geometry>
                <cylinder radius="${wheel_radius}" length="${wheel_thickness}"/>
            </geometry>
        </collision>

        <xacro:inertial mass="${wheel_mass}"/>
    </link>

    <link name="right_wheel">
        <visual>
            <geometry>
                <cylinder radius="${wheel_radius}" length="${wheel_thickness}"/>
            </geometry>
            <origin xyz="0 0 0" rpy="1.57 0 0" />
            <material name="grey" />
        </visual>

        <collision>
            <geometry>
                <cylinder radius="${wheel_radius}" length="${wheel_thickness}"/>
            </geometry>
        </collision>

     <xacro:inertial mass="${wheel_mass}"/>

    </link>

    <link name="caster_wheel">
        <visual>
            <geometry>
                <sphere radius="0.05"/>
            </geometry>
            <origin xyz="0 0 0" rpy="0 0 0" />
            <material name="grey" />
        </visual>

        <inertial>
            <mass value="${wheel_mass}"/>
            <inertia ixx="1e-3" ixy = "0.0" ixz="0.0" iyy="1e-3" iyz="0.0" izz="1e-3"/>
        </inertial>
    </link>


<!-- +++++++++++++++ Camera Link  ++++++++++++++++++-->
    <link name="camera_link">
        <visual>
             <geometry>
                <box size="0.05 0.05 0.05"/>
            </geometry>
                <origin xyz="0 0 0" rpy="0 0 0" />
            <material name="yellow" />
        </visual>
<!-- Collision Geometry-->
    <collision>
        <geometry>
            <box size="0.05 0.05 0.05" />
        </geometry>
    </collision>

<!-- Inertial Properties-->
    <xacro:inertial mass="0.2"/>
    </link>


<!-- Body to Base Joint-->
    <joint name="base_joint" type="fixed">
        <parent link="base_footprint"/>
        <child link="base_link"/>
        <origin xyz="0 0 0.1" rpy="0 0 0"/>
    </joint>
<!--___________________________________________________________-->


<!--Left wheel to Body Joint-->
    <joint name="base_left_wheel_joint" type="continuous">
        <parent link="base_link"/>
        <child link="left_wheel"/>
        <origin xyz="-0.15 0.225 0" rpy="0 0 0"/>
        <axis xyz="0 1 0"/>
<!--Wheel Dynamics -->
        <dynamics damping = "1.0" friction ="0.4"/>
    </joint>
<!--___________________________________________________________-->


<!--Left wheel to Body Joint-->
    <joint name="base_right_wheel_joint" type="continuous">
        <parent link="base_link"/>
        <child link="right_wheel"/>
        <origin xyz="-0.15 -0.225 0" rpy="0 0 0"/>
        <axis xyz="0 1 0"/>
<!--Wheel Dynamics -->
        <dynamics damping = "1.0" friction ="0.4"/>
    </joint>
<!--___________________________________________________________-->


<!--Caster Wheel to Body Joint-->
    <joint name="base_caster_wheel_joint" type="fixed">
        <parent link="base_link"/>
        <child link="caster_wheel"/>
        <origin xyz="0.2 0 -0.05" rpy="0 0 0"/>
    </joint>
<!--___________________________________________________________-->


<!--Camera to Body Joint -->
      <joint name="base_camera_joint" type="fixed">
        <parent link="base_link"/>
        <child link="camera_link"/>
        <origin xyz="${x_dim/2 - 0.05/2} 0 ${z_dim+ (0.05/2)}" rpy="0 0 0"/>
    </joint> 
<!--___________________________________________________________-->


<!-- Camera Joint 

<joint name="camera_optical_joint" type="fixed">
    <parent link="camera_link"/>
    <child link="child_link_optical"/>
    <origin xyz="0.0 0.0 0.0" rpy="0.0 0.0 0.0"/>
</joint>-->



</robot>